{
    "type": "vulnerability",
    "spec_version": "2.1",
    "id": "vulnerability--14a23158-b18f-4d6f-b681-2b7b397eccb6",
    "created_by_ref": "identity--748e6444-f073-4c50-b558-f49be8897a81",
    "created": "2022-08-29T15:15:00.000Z",
    "modified": "2022-10-01T02:31:00.000Z",
    "name": "CVE-2022-0718",
    "description": "A flaw was found in python-oslo-utils. Due to improper parsing, passwords with a double quote ( \" ) in them cause incorrect masking in debug logs, causing any part of the password after the double quote to be plaintext.",
    "external_references": [
        {
            "source_name": "cve",
            "external_id": "CVE-2022-0718"
        },
        {
            "source_name": "cwe",
            "external_id": "CWE-522"
        },
        {
            "source_name": "https://security-tracker.debian.org/tracker/CVE-2022-0718",
            "url": "https://security-tracker.debian.org/tracker/CVE-2022-0718"
        },
        {
            "source_name": "https://bugzilla.redhat.com/show_bug.cgi?id=2056850",
            "url": "https://bugzilla.redhat.com/show_bug.cgi?id=2056850"
        },
        {
            "source_name": "https://access.redhat.com/security/cve/CVE-2022-0718",
            "url": "https://access.redhat.com/security/cve/CVE-2022-0718"
        },
        {
            "source_name": "https://bugs.launchpad.net/oslo.utils/+bug/1949623",
            "url": "https://bugs.launchpad.net/oslo.utils/+bug/1949623"
        },
        {
            "source_name": "https://opendev.org/openstack/oslo.utils/commit/6e17ae1f7959c64dfd20a5f67edf422e702426aa",
            "url": "https://opendev.org/openstack/oslo.utils/commit/6e17ae1f7959c64dfd20a5f67edf422e702426aa"
        },
        {
            "source_name": "[debian-lts-announce] 20220913 [SECURITY] [DLA 3106-1] python-oslo.utils security update",
            "url": "https://lists.debian.org/debian-lts-announce/2022/09/msg00015.html"
        },
        {
            "source_name": "cve2stix",
            "description": "This object was created using cve2stix from the Signals Corps.",
            "url": "https://github.com/signalscorps/cve2stix"
        }
    ],
    "object_marking_refs": [
        "marking-definition--613f2e26-407d-48c7-9eca-b8e91df99dc9"
    ],
    "extensions": {
        "extension-definition--b2b5f2cd-49e6-4091-a0e0-c0bb71543e23": {
            "extension_type": "property-extension",
            "impact": {
                "baseMetricV3": {
                    "cvssV3": {
                        "attackComplexity": "LOW",
                        "attackVector": "NETWORK",
                        "availabilityImpact": "NONE",
                        "baseScore": 4.9,
                        "baseSeverity": "MEDIUM",
                        "confidentialityImpact": "HIGH",
                        "integrityImpact": "NONE",
                        "privilegesRequired": "HIGH",
                        "scope": "UNCHANGED",
                        "userInteraction": "NONE",
                        "vectorString": "CVSS:3.1/AV:N/AC:L/PR:H/UI:N/S:U/C:H/I:N/A:N",
                        "version": "3.1"
                    },
                    "exploitabilityScore": 1.2,
                    "impactScore": 3.6
                }
            },
            "lastModifiedDate": "2022-10-01T02:31Z",
            "nvd_cve": {
                "CVE_data_meta": {
                    "ASSIGNER": "secalert@redhat.com",
                    "ID": "CVE-2022-0718"
                },
                "data_format": "MITRE",
                "data_type": "CVE",
                "data_version": "4.0",
                "description": {
                    "description_data": [
                        {
                            "lang": "en",
                            "value": "A flaw was found in python-oslo-utils. Due to improper parsing, passwords with a double quote ( \" ) in them cause incorrect masking in debug logs, causing any part of the password after the double quote to be plaintext."
                        }
                    ]
                },
                "problemtype": {
                    "problemtype_data": [
                        {
                            "description": [
                                {
                                    "lang": "en",
                                    "value": "CWE-522"
                                }
                            ]
                        }
                    ]
                },
                "references": {
                    "reference_data": [
                        {
                            "name": "https://security-tracker.debian.org/tracker/CVE-2022-0718",
                            "url": "https://security-tracker.debian.org/tracker/CVE-2022-0718",
                            "refsource": "MISC",
                            "tags": [
                                "Patch",
                                "Third Party Advisory"
                            ]
                        },
                        {
                            "name": "https://bugzilla.redhat.com/show_bug.cgi?id=2056850",
                            "url": "https://bugzilla.redhat.com/show_bug.cgi?id=2056850",
                            "refsource": "MISC",
                            "tags": [
                                "Issue Tracking",
                                "Patch",
                                "Third Party Advisory"
                            ]
                        },
                        {
                            "name": "https://access.redhat.com/security/cve/CVE-2022-0718",
                            "url": "https://access.redhat.com/security/cve/CVE-2022-0718",
                            "refsource": "MISC",
                            "tags": [
                                "Third Party Advisory"
                            ]
                        },
                        {
                            "name": "https://bugs.launchpad.net/oslo.utils/+bug/1949623",
                            "url": "https://bugs.launchpad.net/oslo.utils/+bug/1949623",
                            "refsource": "MISC",
                            "tags": [
                                "Exploit",
                                "Issue Tracking",
                                "Patch",
                                "Third Party Advisory"
                            ]
                        },
                        {
                            "name": "https://opendev.org/openstack/oslo.utils/commit/6e17ae1f7959c64dfd20a5f67edf422e702426aa",
                            "url": "https://opendev.org/openstack/oslo.utils/commit/6e17ae1f7959c64dfd20a5f67edf422e702426aa",
                            "refsource": "MISC",
                            "tags": [
                                "Patch",
                                "Vendor Advisory"
                            ]
                        },
                        {
                            "name": "[debian-lts-announce] 20220913 [SECURITY] [DLA 3106-1] python-oslo.utils security update",
                            "url": "https://lists.debian.org/debian-lts-announce/2022/09/msg00015.html",
                            "refsource": "MLIST",
                            "tags": [
                                "Mailing List",
                                "Third Party Advisory"
                            ]
                        }
                    ]
                }
            },
            "publishedDate": "2022-08-29T15:15Z"
        }
    }
}